{"trial_id": "1", "hyperparameters": {"space": [{"class_name": "Int", "config": {"name": "num_layers", "default": null, "conditions": [], "min_value": 1, "max_value": 5, "step": 1, "sampling": "linear"}}, {"class_name": "Int", "config": {"name": "units_0", "default": null, "conditions": [], "min_value": 32, "max_value": 1024, "step": 32, "sampling": "linear"}}, {"class_name": "Float", "config": {"name": "dropout_0", "default": 0.0, "conditions": [], "min_value": 0.0, "max_value": 0.5, "step": 0.1, "sampling": "linear"}}, {"class_name": "Int", "config": {"name": "units_1", "default": null, "conditions": [], "min_value": 32, "max_value": 1024, "step": 32, "sampling": "linear"}}, {"class_name": "Float", "config": {"name": "dropout_1", "default": 0.0, "conditions": [], "min_value": 0.0, "max_value": 0.5, "step": 0.1, "sampling": "linear"}}], "values": {"num_layers": 1, "units_0": 64, "dropout_0": 0.30000000000000004, "units_1": 736, "dropout_1": 0.4}}, "metrics": {"metrics": {}}, "score": null, "best_step": 0, "status": "FAILED", "message": "Traceback (most recent call last):\n  File \"/home/martinus/anaconda3/envs/capstone/lib/python3.11/site-packages/keras_tuner/src/engine/base_tuner.py\", line 274, in _try_run_and_update_trial\n    self._run_and_update_trial(trial, *fit_args, **fit_kwargs)\n  File \"/home/martinus/anaconda3/envs/capstone/lib/python3.11/site-packages/keras_tuner/src/engine/base_tuner.py\", line 239, in _run_and_update_trial\n    results = self.run_trial(trial, *fit_args, **fit_kwargs)\n              ^^^^^^^^^^^^^^^^^^^^^^^^^^^^^^^^^^^^^^^^^^^^^^\n  File \"/home/martinus/anaconda3/envs/capstone/lib/python3.11/site-packages/keras_tuner/src/engine/tuner.py\", line 314, in run_trial\n    obj_value = self._build_and_fit_model(trial, *args, **copied_kwargs)\n                ^^^^^^^^^^^^^^^^^^^^^^^^^^^^^^^^^^^^^^^^^^^^^^^^^^^^^^^^\n  File \"/home/martinus/anaconda3/envs/capstone/lib/python3.11/site-packages/keras_tuner/src/engine/tuner.py\", line 233, in _build_and_fit_model\n    results = self.hypermodel.fit(hp, model, *args, **kwargs)\n              ^^^^^^^^^^^^^^^^^^^^^^^^^^^^^^^^^^^^^^^^^^^^^^^\n  File \"/home/martinus/anaconda3/envs/capstone/lib/python3.11/site-packages/keras_tuner/src/engine/hypermodel.py\", line 149, in fit\n    return model.fit(*args, **kwargs)\n           ^^^^^^^^^^^^^^^^^^^^^^^^^^\n  File \"/home/martinus/anaconda3/envs/capstone/lib/python3.11/site-packages/keras/src/utils/traceback_utils.py\", line 70, in error_handler\n    raise e.with_traceback(filtered_tb) from None\n  File \"/tmp/__autograph_generated_fileke_d1213.py\", line 18, in tf__train_function\n    raise\nValueError: in user code:\n\n    File \"/home/martinus/anaconda3/envs/capstone/lib/python3.11/site-packages/keras/src/engine/training.py\", line 1401, in train_function  *\n        return step_function(self, iterator)\n    File \"/home/martinus/anaconda3/envs/capstone/lib/python3.11/site-packages/keras/src/engine/training.py\", line 1384, in step_function  **\n        outputs = model.distribute_strategy.run(run_step, args=(data,))\n    File \"/home/martinus/anaconda3/envs/capstone/lib/python3.11/site-packages/keras/src/engine/training.py\", line 1373, in run_step  **\n        outputs = model.train_step(data)\n    File \"/home/martinus/anaconda3/envs/capstone/lib/python3.11/site-packages/keras/src/engine/training.py\", line 1151, in train_step\n        loss = self.compute_loss(x, y, y_pred, sample_weight)\n    File \"/home/martinus/anaconda3/envs/capstone/lib/python3.11/site-packages/keras/src/engine/training.py\", line 1209, in compute_loss\n        return self.compiled_loss(\n    File \"/home/martinus/anaconda3/envs/capstone/lib/python3.11/site-packages/keras/src/engine/compile_utils.py\", line 277, in __call__\n        loss_value = loss_obj(y_t, y_p, sample_weight=sw)\n    File \"/home/martinus/anaconda3/envs/capstone/lib/python3.11/site-packages/keras/src/losses.py\", line 143, in __call__\n        losses = call_fn(y_true, y_pred)\n    File \"/home/martinus/anaconda3/envs/capstone/lib/python3.11/site-packages/keras/src/losses.py\", line 270, in call  **\n        return ag_fn(y_true, y_pred, **self._fn_kwargs)\n    File \"/home/martinus/anaconda3/envs/capstone/lib/python3.11/site-packages/keras/src/losses.py\", line 2221, in categorical_crossentropy\n        return backend.categorical_crossentropy(\n    File \"/home/martinus/anaconda3/envs/capstone/lib/python3.11/site-packages/keras/src/backend.py\", line 5573, in categorical_crossentropy\n        target.shape.assert_is_compatible_with(output.shape)\n\n    ValueError: Shapes (None, 1) and (None, 25) are incompatible\n\n"}